[2025-07-25T13:38:25.098+0000] {scheduler_job_runner.py:1562} WARNING - Marking task instance <TaskInstance: sigtap_etl_pipeline.extracao_e_descompactacao manual__2025-07-25T13:27:58.506073+00:00 [queued]> stuck in queued as failed. If the task instance has available retries, it will be retried.
[2025-07-25T13:38:26.192+0000] {scheduler_job_runner.py:769} ERROR - Executor reports task instance <TaskInstance: sigtap_etl_pipeline.extracao_e_descompactacao manual__2025-07-25T13:27:58.506073+00:00 [queued]> finished (failed) although the task says it's queued. (Info: None) Was the task killed externally?
